<robot name="onshape">
    <link name="world">
    <!--Bleibt erstmal leer -->
    </link>

    <joint name="fixed_link_to_world" type="fixed">
        <parent link="world"/>
        <child link="base"/>
    </joint>   
    <link name="base">
        <visual>
            <origin xyz="-4.1633363423443370266e-17 1.6949752565162061855e-18 -5.5154662533553587949e-34" rpy="-3.254009893154236877e-16 8.6281661508548166217e-32 1.2347465433156991646e-16" />
            <geometry>
                <mesh filename="package://sero_3/meshes/base.stl" />
            </geometry>
            <material name="base_material">
                <color rgba="0.89019607843137249503 0.69803921568627447236 0.63921568627450975342 1.0" />
            </material>
        </visual>
        <collision>
            <origin xyz="-4.1633363423443370266e-17 1.6949752565162061855e-18 -5.5154662533553587949e-34" rpy="-3.254009893154236877e-16 8.6281661508548166217e-32 1.2347465433156991646e-16" />
            <geometry>
                <mesh filename="package://sero_3/meshes/base.stl" />
            </geometry>
        </collision>
        <inertial>
            <origin xyz="-1.4191131412431651619e-17 3.093208156293898791e-17 0.039865010471469702891" rpy="0 0 0" />
            <mass value="29.561020908170693389" />
            <inertia ixx="0.56414288287999059257" ixy="6.1629758220391547298e-32" ixz="-2.6008615487439589667e-32" iyy="0.5641428828799902595" iyz="1.5651332502670880486e-16" izz="1.0451288975690682381" />
        </inertial>
    </link>
    <link name="link_1">
        <visual>
            <origin xyz="-6.1629758220391547298e-33 4.8470540592812887996e-18 0" rpy="3.141592653589793116 -2.0861283505423087262e-43 0" />
            <geometry>
                <mesh filename="package://sero_3/meshes/link_1.stl" />
            </geometry>
            <material name="link_1_material">
                <color rgba="0.92156862745098033773 0.80000000000000004441 0.65490196078431373028 1.0" />
            </material>
        </visual>
        <collision>
            <origin xyz="-6.1629758220391547298e-33 4.8470540592812887996e-18 0" rpy="3.141592653589793116 -2.0861283505423087262e-43 0" />
            <geometry>
                <mesh filename="package://sero_3/meshes/link_1.stl" />
            </geometry>
        </collision>
        <inertial>
            <origin xyz="2.5812154935817390889e-07 0.020078728528027917077 -0.084265679701914092403" rpy="0 0 0" />
            <!--
            <mass value="32.098264787234505491" /> -->
            <mass value="20" />
            <inertia ixx="0.15183599668872910238" ixy="-1.1318804273050995291e-06" ixz="4.1015787527610980043e-07" iyy="0.12206161215963268196" iyz="0.00514067802598717951" izz="0.12973629061825234232" />
        </inertial>
    </link>
    <link name="link_2">
        <visual>
            <origin xyz="0 4.5924254968025766839e-18 4.1183628318625710158e-18" rpy="-3.141592653589793116 9.8607613152626475676e-32 -1.3749793942868710628e-32" />
            <geometry>
                <mesh filename="package://sero_3/meshes/link_2.stl" />
            </geometry>
            <material name="link_2_material">
                <color rgba="0.94117647058823528106 0.87450980392156862919 0.67843137254901964006 1.0" />
            </material>
        </visual>
        <collision>
            <origin xyz="0 4.5924254968025766839e-18 4.1183628318625710158e-18" rpy="-3.141592653589793116 9.8607613152626475676e-32 -1.3749793942868710628e-32" />
            <geometry>
                <mesh filename="package://sero_3/meshes/link_2.stl" />
            </geometry>
        </collision>
        <inertial>
            <origin xyz="-0.31499983020000299483 -5.9338950341248018232e-08 -0.1048694271057695887" rpy="0 0 0" />
            <!--
            <mass value="95.412481284338156229" /> -->
            <mass value="10" />
            <inertia ixx="0.30014578780677336756" ixy="2.7683924706706791416e-07" ixz="2.5259250984795803334e-06" iyy="5.0701114070706099213" iyz="-3.3364583905554261746e-07" izz="4.9823951617652841861" />
        </inertial>
    </link>
    <link name="link_3">
        <visual>
            <origin xyz="0 0 -3.5177085194790902871e-18" rpy="1.570796326794896558 -1.9721522630525295135e-31 1.3755759769189022776e-33" />
            <geometry>
                <mesh filename="package://sero_3/meshes/link_3.stl" />
            </geometry>
            <material name="link_3_material">
                <color rgba="0.79607843137254896693 0.90588235294117647189 0.74509803921568629193 1.0" />
            </material>
        </visual>
        <collision>
            <origin xyz="0 0 -3.5177085194790902871e-18" rpy="1.570796326794896558 -1.9721522630525295135e-31 1.3755759769189022776e-33" />
            <geometry>
                <mesh filename="package://sero_3/meshes/link_3.stl" />
            </geometry>
        </collision>
        <inertial>
            <origin xyz="-0.12787550742648204349 -0.086695678159673439378 -0.13092497492624188826" rpy="0 0 0" />
            <!--
            <mass value="84.06211694702932391" /> -->
            <mass value="5" />
            <inertia ixx="0.72701390054885139946" ixy="-0.56396100688611627838" ixz="-0.3398755684914888664" iyy="2.2596801602232305939" iyz="-0.076724939144711401529" izz="2.471848827686650818" />
        </inertial>
    </link>
    <link name="link_4">
        <visual>
            <origin xyz="0 0 3.0295804379226702294e-18" rpy="3.141592653589793116 -0 -3.8393994794198495367e-32" />
            <geometry>
                <mesh filename="package://sero_3/meshes/link_4.stl" />
            </geometry>
            <material name="link_4_material">
                <color rgba="0.73725490196078435901 0.9372549019607843146 0.91764705882352937127 1.0" />
            </material>
        </visual>
        <collision>
            <origin xyz="0 0 3.0295804379226702294e-18" rpy="3.141592653589793116 -0 -3.8393994794198495367e-32" />
            <geometry>
                <mesh filename="package://sero_3/meshes/link_4.stl" />
            </geometry>
        </collision>
        <inertial>
            <origin xyz="-0.0057366460591120483486 -0.056799838397228498421 -0.078907548477852723634" rpy="0 0 0" />
            <!--
            <mass value="35.563010627334307401" /> -->
            <mass value="10" />
            <inertia ixx="0.14795985643388004371" ixy="-0.006773630552061549355" ixz="-0.00022289820645230695706" iyy="0.19264265280028286531" iyz="-0.002206662293176273916" izz="0.2475639065566472008" />
        </inertial>
    </link>
    <link name="ee_base">
        <visual>
            <origin xyz="6.6613381471808452436e-18 0 -0.080000000000000071054" rpy="3.141592653589793116 -0 0" />
            <geometry>
                <mesh filename="package://sero_3/meshes/ee_base.stl" />
            </geometry>
            <material name="ee_base_material">
                <color rgba="0.76078431372549015776 0.83921568627450982003 0.92549019607843141522 1.0" />
            </material>
        </visual>
        <collision>
            <origin xyz="6.6613381471808452436e-18 0 -0.080000000000000071054" rpy="3.141592653589793116 -0 0" />
            <geometry>
                <mesh filename="package://sero_3/meshes/ee_base.stl" />
            </geometry>
        </collision>
        <inertial>
            <origin xyz="9.8538615821355001922e-18 1.3275424895558869447e-17 -0.0057551348153010856157" rpy="0 0 0" />
            <!--
            <mass value="13.798178184326982176" /> -->
            <mass value="5" />
            <inertia ixx="0.028682988283033793858" ixy="0" ixz="0" iyy="0.074982477117703713598" iyz="6.2565298301991734419e-33" izz="0.097983436923002042995" />
        </inertial>
    </link>
    <link name="v_tube">
        <visual>
            <origin xyz="0 -8.326672683761289173e-18 -0.044999999999999928946" rpy="3.141592653589793116 1.0342508817956038219e-31 0" />
            <geometry>
                <mesh filename="package://sero_3/meshes/v_tube.stl" />
            </geometry>
            <material name="v_tube_material">
                <color rgba="0.80000000000000004441 0.74901960784313725839 0.91372549019607840481 1.0" />
            </material>
        </visual>
        <collision>
            <origin xyz="0 -8.326672683761289173e-18 -0.044999999999999928946" rpy="3.141592653589793116 1.0342508817956038219e-31 0" />
            <geometry>
                <mesh filename="package://sero_3/meshes/v_tube.stl" />
            </geometry>
        </collision>
        <inertial>
            <origin xyz="1.7426086658785223658e-19 -8.326672683761289173e-18 -0.023353658507928257843" rpy="0 0 0" />
            <mass value="0.16852026592631189073" />
            <inertia ixx="3.3195910788590593564e-05" ixy="-6.5467390585808818723e-36" ixz="-3.6792700159404011462e-36" iyy="3.3195910788590593564e-05" iyz="0" izz="1.3625480037700539164e-05" />
        </inertial>
    </link>
    <joint name="vacuum_1" type="fixed">
        <origin xyz="0.094999999999999987232 0.044999999999999706901 -0.035000000000000031086" rpy="-2.5673907444551896414e-16 -4.5080215706672108797e-30 1.570796326794896558" />
        <parent link="ee_base" />
        <child link="v_tube" />
        <axis xyz="0 0 1" />
        <limit effort="1" velocity="3.14" />
        <dynamics damping="0.5" friction="0.5" />
    </joint>
    <link name="v_tube_2">
        <visual>
            <origin xyz="0 -4.9960036098762270031e-18 -0.044999999999999928946" rpy="3.141592653589793116 1.0342508817956038219e-31 0" />
            <geometry>
                <mesh filename="package://sero_3/meshes/v_tube.stl" />
            </geometry>
            <material name="v_tube_material">
                <color rgba="0.80000000000000004441 0.74901960784313725839 0.91372549019607840481 1.0" />
            </material>
        </visual>
        <collision>
            <origin xyz="0 -4.9960036098762270031e-18 -0.044999999999999928946" rpy="3.141592653589793116 1.0342508817956038219e-31 0" />
            <geometry>
                <mesh filename="package://sero_3/meshes/v_tube.stl" />
            </geometry>
        </collision>
        <inertial>
            <origin xyz="1.7426086658785223658e-19 -4.9960036098762270031e-18 -0.023353658507928257843" rpy="0 0 0" />
            <mass value="0.16852026592631189073" />
            <inertia ixx="3.3195910788590593564e-05" ixy="-6.5467390585808818723e-36" ixz="-3.6792700159404011462e-36" iyy="3.3195910788590593564e-05" iyz="0" izz="1.3625480037700539164e-05" />
        </inertial>
    </link>
    <joint name="vacuum_2" type="fixed">
        <origin xyz="0.095000000000000014988 -0.04500000000000015099 -0.035000000000000031086" rpy="-2.5673907444551896414e-16 -4.5080215706672108797e-30 1.570796326794896558" />
        <parent link="ee_base" />
        <child link="v_tube_2" />
        <axis xyz="0 0 1" />
        <limit effort="1" velocity="3.14" />
        <dynamics damping="0.5" friction="0.5" />
    </joint>
    <link name="v_tube_3">
        <visual>
            <origin xyz="0 5.5511151240626339132e-18 -0.044999999999999928946" rpy="3.141592653589793116 1.0342508817956038219e-31 0" />
            <geometry>
                <mesh filename="package://sero_3/meshes/v_tube.stl" />
            </geometry>
            <material name="v_tube_material">
                <color rgba="0.80000000000000004441 0.74901960784313725839 0.91372549019607840481 1.0" />
            </material>
        </visual>
        <collision>
            <origin xyz="0 5.5511151240626339132e-18 -0.044999999999999928946" rpy="3.141592653589793116 1.0342508817956038219e-31 0" />
            <geometry>
                <mesh filename="package://sero_3/meshes/v_tube.stl" />
            </geometry>
        </collision>
        <inertial>
            <origin xyz="1.7426086658785223658e-19 5.5511151240626331428e-18 -0.023353658507928257843" rpy="0 0 0" />
            <mass value="0.16852026592631189073" />
            <inertia ixx="3.3195910788590593564e-05" ixy="-6.5467390585808818723e-36" ixz="-3.6792700159404011462e-36" iyy="3.3195910788590593564e-05" iyz="0" izz="1.3625480037700539164e-05" />
        </inertial>
    </link>
    <joint name="vacuum_3" type="fixed">
        <origin xyz="-0.094999999999999987232 0.044999999999999706901 -0.035000000000000031086" rpy="-2.5673907444551896414e-16 -4.5080215706672108797e-30 1.570796326794896558" />
        <parent link="ee_base" />
        <child link="v_tube_3" />
        <axis xyz="0 0 1" />
        <limit effort="1" velocity="3.14" />
        <dynamics damping="0.5" friction="0.5" />
    </joint>
    <link name="v_tube_4">
        <visual>
            <origin xyz="0 8.8817841979453295003e-18 -0.044999999999999928946" rpy="3.141592653589793116 1.0342508817956038219e-31 0" />
            <geometry>
                <mesh filename="package://sero_3/meshes/v_tube.stl" />
            </geometry>
            <material name="v_tube_material">
                <color rgba="0.80000000000000004441 0.74901960784313725839 0.91372549019607840481 1.0" />
            </material>
        </visual>
        <collision>
            <origin xyz="0 8.8817841979453295003e-18 -0.044999999999999928946" rpy="3.141592653589793116 1.0342508817956038219e-31 0" />
            <geometry>
                <mesh filename="package://sero_3/meshes/v_tube.stl" />
            </geometry>
        </collision>
        <inertial>
            <origin xyz="1.7426086658785223658e-19 8.8817841979453295003e-18 -0.023353658507928257843" rpy="0 0 0" />
            <mass value="0.16852026592631189073" />
            <inertia ixx="3.3195910788590593564e-05" ixy="-6.5467390585808818723e-36" ixz="-3.6792700159404011462e-36" iyy="3.3195910788590593564e-05" iyz="0" izz="1.3625480037700539164e-05" />
        </inertial>
    </link>
    <joint name="vacuum_4" type="fixed">
        <origin xyz="-0.094999999999999959477 -0.045000000000000373035 -0.035000000000000031086" rpy="-2.5673907444551896414e-16 -4.5080215706672108797e-30 1.570796326794896558" />
        <parent link="ee_base" />
        <child link="v_tube_4" />
        <axis xyz="0 0 1" />
        <limit effort="1" velocity="3.14" />
        <dynamics damping="0.5" friction="0.5" />
    </joint>
    <joint name="j5" type="revolute">
        <origin xyz="0.14499999999999985123 -0.090000000000000301981 -0.079999999999999987788" rpy="-3.141592653589793116 1.5707963267948890085 0" />
        <parent link="link_4" />
        <child link="ee_base" />
        <axis xyz="0 0 1" />
        <limit effort="1000" velocity="3.14" lower="-3.141592653589793116" upper="3.141592653589793116" />
        <dynamics damping="1.0" friction="1.0" />
    </joint>
    <joint name="j4" type="revolute">
        <origin xyz="-0.49500000000000005107 -0.14000000000000001332 -0.17000000000000009548" rpy="3.1415926535897917837 6.241086271459160841e-16 -3.1415926535897922278" />
        <parent link="link_3" />
        <child link="link_4" />
        <axis xyz="0 0 1" />
        <limit effort="1000" velocity="3.14" lower="-3.141592653589793116" upper="3.141592653589793116" />
        <dynamics damping="1.0" friction="1.0" />
    </joint>
    <joint name="j3" type="revolute">
        <origin xyz="-0.62999999999999989342 -6.4711246131411124663e-32 1.061085658197035173e-17" rpy="-3.141592653589793116 -1.819226480685986761e-15 1.5707963267948961139" />
        <parent link="link_2" />
        <child link="link_3" />
        <axis xyz="0 0 1" />
        <limit effort="1000" velocity="3.14" lower="-3.141592653589793116" upper="3.141592653589793116" />
        <dynamics damping="1.0" friction="1.0" />
    </joint>
    <joint name="j2" type="revolute">
        <origin xyz="-6.1629758220391547298e-33 0.12000000000000005107 -0.079999999999999960032" rpy="1.5707963267948956698 -1.5707963267948956698 0" />
        <parent link="link_1" />
        <child link="link_2" />
        <axis xyz="0 0 1" />
        <limit effort="9000" velocity="3.14" lower="-1.5708" upper="1.5708" />
        <dynamics damping="1.0" friction="1.0" />
    </joint>
    <joint name="j1" type="revolute">
        <origin xyz="-4.1633363423443370266e-17 6.2524054036301313582e-17 0.17000000000000001221" rpy="3.141592653589793116 -3.5404820457539550914e-27 -5.5511151231290971505e-17" />
        <parent link="base" />
        <child link="link_1" />
        <axis xyz="0 0 1" />
        <limit effort="100" velocity="3.14" lower="-3.141592653589793116" upper="3.141592653589793116" />
        <dynamics damping="1.0" friction="1.0" />
    </joint>
    <!--MoveIt Setup Assistant -->
    <transmission name="trans_j5">
        <type>transmission_interface/SimpleTransmission</type>
        <joint name="j5">
            <hardwareInterface>hardware_interface/EffortJointInterface</hardwareInterface>
        </joint>
        <actuator name="j5_motor">
            <hardwareInterface>hardware_interface/EffortJointInterface</hardwareInterface>
            <mechanicalReduction>1</mechanicalReduction>
        </actuator>
    </transmission>
    <transmission name="trans_j4">
        <type>transmission_interface/SimpleTransmission</type>
        <joint name="j4">
            <hardwareInterface>hardware_interface/EffortJointInterface</hardwareInterface>
        </joint>
        <actuator name="j4_motor">
            <hardwareInterface>hardware_interface/EffortJointInterface</hardwareInterface>
            <mechanicalReduction>1</mechanicalReduction>
        </actuator>
    </transmission>
    <transmission name="trans_j3">
        <type>transmission_interface/SimpleTransmission</type>
        <joint name="j3">
            <hardwareInterface>hardware_interface/EffortJointInterface</hardwareInterface>
        </joint>
        <actuator name="j3_motor">
            <hardwareInterface>hardware_interface/EffortJointInterface</hardwareInterface>
            <mechanicalReduction>1</mechanicalReduction>
        </actuator>
    </transmission>
    <transmission name="trans_j2">
        <type>transmission_interface/SimpleTransmission</type>
        <joint name="j2">
            <hardwareInterface>hardware_interface/EffortJointInterface</hardwareInterface>
        </joint>
        <actuator name="j2_motor">
            <hardwareInterface>hardware_interface/EffortJointInterface</hardwareInterface>
            <mechanicalReduction>1</mechanicalReduction>
        </actuator>
    </transmission>
    <transmission name="trans_j1">
        <type>transmission_interface/SimpleTransmission</type>
        <joint name="j1">
            <hardwareInterface>hardware_interface/EffortJointInterface</hardwareInterface>
        </joint>
        <actuator name="j1_motor">
            <hardwareInterface>hardware_interface/EffortJointInterface</hardwareInterface>
            <mechanicalReduction>1</mechanicalReduction>
        </actuator>
    </transmission>

    <!--Gazebo Plugins -->
    <gazebo>
        <plugin name="control" filename="libgazebo_ros_control.so">
            <robotNamespace>/</robotNamespace>
        </plugin>
    </gazebo>
    <gazebo>
        <plugin name = "joint_state_publisher" filename = "libgazebo_ros_joint_state_publisher.so" >
        <jointName>j1, j2, j3, j4, j5 </jointName>
        </plugin>
    </gazebo>
</robot>
