<robot name="onshape">
<link name="base">
<visual>
<origin xyz="1.8041124150158793782e-16 0.05566523198650896731 0" rpy="0 -0 0" />
<geometry>
<mesh filename="package:///base.stl"/>
</geometry>
<material name="base_material">
<color rgba="0.89019607843137249503 0.69803921568627447236 0.63921568627450975342 1.0"/>
</material>
</visual>
<collision>
<origin xyz="1.8041124150158793782e-16 0.05566523198650896731 0" rpy="0 -0 0" />
<geometry>
<mesh filename="package:///base.stl"/>
</geometry>
</collision>
<inertial>
<origin xyz="1.1000115286909761609e-10 0.028213959507363061546 0.048033342389235664238" rpy="0 0 0"/>
<mass value="35.087052395247894765" />
<inertia ixx="0.23851697130036858541" ixy="2.7207825003648302405e-10"  ixz="-1.0025050118003768389e-10" iyy="0.15387922346861426792" iyz="0.0068756425646022177947" izz="0.32171277328667868822" />
</inertial>
</link>

<link name="link_1">
<visual>
<origin xyz="0 6.9388939039072283776e-18 0" rpy="3.141592653589793116 -0 0" />
<geometry>
<mesh filename="package:///link_1.stl"/>
</geometry>
<material name="link_1_material">
<color rgba="0.92156862745098033773 0.80000000000000004441 0.65490196078431373028 1.0"/>
</material>
</visual>
<collision>
<origin xyz="0 6.9388939039072283776e-18 0" rpy="3.141592653589793116 -0 0" />
<geometry>
<mesh filename="package:///link_1.stl"/>
</geometry>
</collision>
<inertial>
<origin xyz="-0.015239689133278305766 -0.021586960622581669034 -0.052922200956408933792" rpy="0 0 0"/>
<mass value="18.368766956758115327" />
<inertia ixx="0.091881923345227559108" ixy="-0.0039285078233497914765"  ixz="-0.0058549145264777313277" iyy="0.077315975512156742688" iyz="-0.018619533982869220651" izz="0.081329742201552590597" />
</inertial>
</link>

<link name="link_2">
<visual>
<origin xyz="-1.387778780780972359e-17 0 0" rpy="-3.141592653589793116 -0 0" />
<geometry>
<mesh filename="package:///link_2.stl"/>
</geometry>
<material name="link_2_material">
<color rgba="0.94117647058823528106 0.87450980392156862919 0.67843137254901964006 1.0"/>
</material>
</visual>
<collision>
<origin xyz="-1.387778780780972359e-17 0 0" rpy="-3.141592653589793116 -0 0" />
<geometry>
<mesh filename="package:///link_2.stl"/>
</geometry>
</collision>
<inertial>
<origin xyz="-9.7069511863613003069e-09 0.21218755221227944552 -0.047778672194229002135" rpy="0 0 0"/>
<mass value="23.673948033547031145" />
<inertia ixx="0.65581612438466785342" ixy="-4.2793701147829384543e-08"  ixz="1.457960283279840245e-08" iyy="0.037401631785456156132" iyz="0.0087992679245661210852" izz="0.65336519359711109356" />
</inertial>
</link>

<link name="link_3">
<visual>
<origin xyz="-2.7755575615530700328e-18 0 -0.02999999999999999889" rpy="-1.2325951644068986172e-32 -0 9.8607613152626475676e-32" />
<geometry>
<mesh filename="package:///link_3.stl"/>
</geometry>
<material name="link_3_material">
<color rgba="0.79607843137254896693 0.90588235294117647189 0.74509803921568629193 1.0"/>
</material>
</visual>
<collision>
<origin xyz="-2.7755575615530700328e-18 0 -0.02999999999999999889" rpy="-1.2325951644068986172e-32 -0 9.8607613152626475676e-32" />
<geometry>
<mesh filename="package:///link_3.stl"/>
</geometry>
</collision>
<inertial>
<origin xyz="0.11674575857875567342 0.092289914347079254897 0.0096232090141137455186" rpy="0 0 0"/>
<mass value="17.046409404154790224" />
<inertia ixx="0.074800627899214836014" ixy="-0.036857779963696400694"  ixz="-0.0059546580572337080503" iyy="0.078894656681966157663" iyz="-0.011906977912637868935" izz="0.11406256275854879945" />
</inertial>
</link>

<link name="link_4">
<visual>
<origin xyz="0 0 3.7692998288682504122e-18" rpy="3.141592653589793116 -0 1.117039367744614311e-32" />
<geometry>
<mesh filename="package:///link_4.stl"/>
</geometry>
<material name="link_4_material">
<color rgba="0.73725490196078435901 0.9372549019607843146 0.91764705882352937127 1.0"/>
</material>
</visual>
<collision>
<origin xyz="0 0 3.7692998288682504122e-18" rpy="3.141592653589793116 -0 1.117039367744614311e-32" />
<geometry>
<mesh filename="package:///link_4.stl"/>
</geometry>
</collision>
<inertial>
<origin xyz="3.2977564248997069275e-09 -0.02702676809649579362 -0.062304227824277497172" rpy="0 0 0"/>
<mass value="3.4104383191089318039" />
<inertia ixx="0.013598205960530259859" ixy="3.5112585733289065571e-10"  ixz="-2.2034950619188486669e-10" iyy="0.013866957658279771906" iyz="-0.0019762165524031542925" izz="0.0046399785925361671651" />
</inertial>
</link>

<link name="link_5">
<visual>
<origin xyz="0 5.7502599639108928044e-19 -0.059000000000000010769" rpy="0 -6.2400130198011916986e-32 0" />
<geometry>
<mesh filename="package:///link_5.stl"/>
</geometry>
<material name="link_5_material">
<color rgba="0.76078431372549015776 0.83921568627450982003 0.92549019607843141522 1.0"/>
</material>
</visual>
<collision>
<origin xyz="0 5.7502599639108928044e-19 -0.059000000000000010769" rpy="0 -6.2400130198011916986e-32 0" />
<geometry>
<mesh filename="package:///link_5.stl"/>
</geometry>
</collision>
<inertial>
<origin xyz="-4.046842952832385703e-09 0.039174510825137690007 -0.02949999933510723607" rpy="0 0 0"/>
<mass value="1.3085442124892889826" />
<inertia ixx="0.0013064926249374245355" ixy="9.9120581365052454889e-11"  ixz="-1.9731401884107245413e-09" iyy="0.00068551260771868721428" iyz="-5.9177390752194953409e-12" izz="0.0010923022573062724991" />
</inertial>
</link>

<link name="endeffector">
<visual>
<origin xyz="0 -0.060000000000000053291 -0.010000000000000050515" rpy="3.141592653589793116 -0 -2.1802971418028674515e-29" />
<geometry>
<mesh filename="package:///endeffector.stl"/>
</geometry>
<material name="endeffector_material">
<color rgba="0.80000000000000004441 0.74901960784313725839 0.91372549019607840481 1.0"/>
</material>
</visual>
<collision>
<origin xyz="0 -0.060000000000000053291 -0.010000000000000050515" rpy="3.141592653589793116 -0 -2.1802971418028674515e-29" />
<geometry>
<mesh filename="package:///endeffector.stl"/>
</geometry>
</collision>
<inertial>
<origin xyz="-2.0079276286738393323e-08 -0.055461111974627948229 -0.097485938408557751278" rpy="0 0 0"/>
<mass value="2.2359613690447335266" />
<inertia ixx="0.020791268849754431652" ixy="-8.8059871773715884785e-10"  ixz="1.9141237193218601493e-10" iyy="0.020196057963709126287" iyz="-0.00095402857951714292641" izz="0.0010816277361651645706" />
</inertial>
</link>

<joint name="6" type="revolute">
<origin xyz="1.1102230246251565404e-16 0.080000000000000001665 -0.029500000000000005385" rpy="1.5707963267948958919 1.57079632679465786 0" />
<parent link="link_5" />
<child link="endeffector" />
<axis xyz="0 0 1"/>
<limit effort="1" velocity="20" />
<joint_properties friction="0.0"/>
</joint>

<joint name="5" type="revolute">
<origin xyz="-0.030000000000000005829 -0.035000000000000031086 -0.18499999999999997002" rpy="-1.570796326794896558 1.8752360775309906313e-14 1.570796326794901665" />
<parent link="link_4" />
<child link="link_5" />
<axis xyz="0 0 1"/>
<limit effort="1" velocity="20" />
<joint_properties friction="0.0"/>
</joint>

<joint name="4" type="revolute">
<origin xyz="0.22000000000000724532 0.12083333333333379223 -0.016980779096483905599" rpy="3.1415926535897926719 1.570796326794891673 0" />
<parent link="link_3" />
<child link="link_4" />
<axis xyz="0 0 1"/>
<limit effort="1" velocity="20" />
<joint_properties friction="0.0"/>
</joint>

<joint name="3" type="revolute">
<origin xyz="-1.9428902930931246443e-17 0.44999999999999978906 8.0074835651082891598e-16" rpy="3.1415926535897864547 2.2759572004824394437e-15 -3.1415926535897926719" />
<parent link="link_2" />
<child link="link_3" />
<axis xyz="0 0 1"/>
<limit effort="1" velocity="20" />
<joint_properties friction="0.0"/>
</joint>

<joint name="2" type="revolute">
<origin xyz="-6.9388939039073269853e-18 -0.059999999999999248379 -0.14500000000000001776" rpy="-1.57079632679489678 -2.2204460492503342815e-16 1.5707963267948943376" />
<parent link="link_1" />
<child link="link_2" />
<axis xyz="0 0 1"/>
<limit effort="1" velocity="20" />
<joint_properties friction="0.0"/>
</joint>

<joint name="1" type="revolute">
<origin xyz="1.873501354054951662e-16 0.055665231986508974249 0.10499999999999998224" rpy="3.141592653589793116 -0 0" />
<parent link="base" />
<child link="link_1" />
<axis xyz="0 0 1"/>
<limit effort="1" velocity="20" />
<joint_properties friction="0.0"/>
</joint>


</robot>
